<?xml version="1.0"?>
<robot name="triped">
    
    <material name="chassis_material">
        <color rgba="1.0 0.63529414 0.0 1.0"/>
    </material>

    <material name="extend_material">
        <color rgba="0.60784316 0.6509804 0.05882353 1.0"/>
    </material>

    <material name="drive_module_material">
        <color rgba="0.0 0.39607844 0.44705883 1.0"/>
    </material>

 
 

    <link name="chassis">
        <visual>
            <origin rpy="0.0 0.0 0.0" xyz="0.0 0.0 0.0"/>
            <geometry>
                <mesh filename="chassis.stl" scale="0.001 0.001 0.001"/>
            </geometry>
            <material name="chassis_material"/>
        </visual>
        <collision>
           <origin rpy="0.0 0.0 0.0" xyz="0.0 0.0 0.0"/>
           <geometry>
                <mesh filename="chassis.stl" scale="0.001 0.001 0.001"/>
           </geometry>
        </collision>
        <inertial>
            <origin xyz="0 0 0.01044" rpy="0.0 0.0 0.0"/>
            <mass value="10.414"/>
            <inertia ixx="0.127" ixy="0.0" ixz="0.0" iyy=" 0.127" iyz="0.0" izz="0.209"/>
        </inertial>
    </link>

    <link name="leg_0_rotX">
        <inertial>
            <origin xyz="0 0 0.0" rpy="0.0 0.0 0.0"/>
            <mass value="0"/>
            <inertia ixx="0.0" ixy="0.0" ixz="0.0" iyy=" 0.0" iyz="0.0" izz="0.0"/>
        </inertial>
    </link>
    <link name="leg_0_rotY">
        <inertial>
            <origin xyz="0 0 0.0" rpy="0.0 0.0 0.0"/>
            <mass value="0"/>
            <inertia ixx="0.0" ixy="0.0" ixz="0.0" iyy=" 0.0" iyz="0.0" izz="0.0"/>
        </inertial>
    </link>
    <link name="leg_1_rotX">
        <inertial>
            <origin xyz="0 0 0.0" rpy="0.0 0.0 0.0"/>
            <mass value="0"/>
            <inertia ixx="0.0" ixy="0.0" ixz="0.0" iyy=" 0.0" iyz="0.0" izz="0.0"/>
        </inertial>
    </link>
    <link name="leg_1_rotY">
        <inertial>
            <origin xyz="0 0 0.0" rpy="0.0 0.0 0.0"/>
            <mass value="0"/>
            <inertia ixx="0.0" ixy="0.0" ixz="0.0" iyy=" 0.0" iyz="0.0" izz="0.0"/>
        </inertial>
    </link>
    <link name="leg_2_rotX">
        <inertial>
            <origin xyz="0 0 0.0" rpy="0.0 0.0 0.0"/>
            <mass value="0"/>
            <inertia ixx="0.0" ixy="0.0" ixz="0.0" iyy=" 0.0" iyz="0.0" izz="0.0"/>
        </inertial>
    </link>
    <link name="leg_2_rotY">
        <inertial>
            <origin xyz="0 0 0.0" rpy="0.0 0.0 0.0"/>
            <mass value="0"/>
            <inertia ixx="0.0" ixy="0.0" ixz="0.0" iyy=" 0.0" iyz="0.0" izz="0.0"/>
        </inertial>
    </link>      

    <link name="leg_0_drive_module">
        <visual>
            <origin xyz="0.0 0.0 0.0" rpy="0.0 0.0 0.0"/>
            <geometry>
                <mesh filename="drive_module.stl" scale="0.001 0.001 0.001"/>
            </geometry>
            <material name="drive_module_material"/>
        </visual>
        <inertial>
            <origin xyz="0.0259 0.0507 0.0455" rpy="0.0 0.0 0.0"/>
            <mass value="1.908"/>
            <inertia ixx="0.005" ixy="0.0" ixz="0.0" iyy="0.007" iyz="0.0" izz="0.008"/>
        </inertial>
    </link>
    <link name="leg_1_drive_module">
        <visual>
            <origin xyz="0.0 0.0 0.0" rpy="0.0 0.0 0.0"/>
            <geometry>
                <mesh filename="drive_module.stl" scale="0.001 0.001 0.001"/>
            </geometry>
            <material name="drive_module_material"/>
        </visual>
        <inertial>
            <origin xyz="0.0259 0.0507 0.0455" rpy="0.0 0.0 0.0"/>
            <mass value="1.908"/>
            <inertia ixx="0.005" ixy="0.0" ixz="0.0" iyy="0.007" iyz="0.0" izz="0.008"/>
        </inertial>
    </link>
    <link name="leg_2_drive_module">
        <visual>
            <origin xyz="0.0 0.0 0.0" rpy="0.0 0.0 0.0"/>
            <geometry>
                <mesh filename="drive_module.stl" scale="0.001 0.001 0.001"/>
            </geometry>
            <material name="drive_module_material"/>
        </visual>
        <inertial>
            <origin xyz="0.0259 0.0507 0.0455" rpy="0.0 0.0 0.0"/>
            <mass value="1.908"/>
            <inertia ixx="0.005" ixy="0.0" ixz="0.0" iyy="0.007" iyz="0.0" izz="0.008"/>
        </inertial>
    </link>

    <link name="leg_0_open">
        <visual>
            <origin xyz="-1.500 0.0 0.0" rpy="0.0 0.0 0.0"/>
            <geometry>
                <mesh filename="leg_linear.stl" scale="0.001 0.001 0.001"/>
            </geometry>
            <material name="extend_material"/>
        </visual>
        <collision>
            <origin xyz="-1.500 0.0 0.0" rpy="0.0 0.0 0.0"/>
            <geometry>
                <sphere radius="0.03"/>
            </geometry>
        </collision>
        <inertial>
            <origin xyz="0.094275 0 0.452725" rpy="0.0 0.0 0.0"/>
            <mass value="0.503"/>
            <inertia ixx="0.0006157" ixy="0.0" ixz="0.0" iyy="0.047" iyz="0.0" izz="0.047"/>
        </inertial>
    </link>
    <link name="leg_1_open">
        <visual>
            <origin xyz="-1.500 0.0 0.0" rpy="0.0 0.0 0.0"/>
            <geometry>
                <mesh filename="leg_linear.stl" scale="0.001 0.001 0.001"/>
            </geometry>
            <material name="extend_material"/>
        </visual>
        <collision>
            <origin xyz="-1.500 0.0 0.0" rpy="0.0 0.0 0.0"/>
            <geometry>
                <sphere radius="0.03"/>
            </geometry>
        </collision>
        <inertial>
            <origin xyz="0.094275 0 0.452725" rpy="0.0 0.0 0.0"/>
            <mass value="0.503"/>
            <inertia ixx="0.0006157" ixy="0.0" ixz="0.0" iyy="0.047" iyz="0.0" izz="0.047"/>
        </inertial>
    </link>
    <link name="leg_2_open">
        <visual>
            <origin xyz="-1.500 0.0 0.0" rpy="0.0 0.0 0.0"/>
            <geometry>
                <mesh filename="leg_linear.stl" scale="0.001 0.001 0.001"/>
            </geometry>
            <material name="extend_material"/>
        </visual>
        <collision>
            <origin xyz="-1.500 0.0 0.0" rpy="0.0 0.0 0.0"/>
            <geometry>
                <sphere radius="0.03"/>
            </geometry>
        </collision>
        <inertial>
            <origin xyz="0.094275 0 0.452725" rpy="0.0 0.0 0.0"/>
            <mass value="0.503"/>
            <inertia ixx="0.0006157" ixy="0.0" ixz="0.0" iyy="0.047" iyz="0.0" izz="0.047"/>
        </inertial>
    </link>

    <!-- joints of the robot -->
    <joint name="leg_0_LCSX" type="revolute">
        <parent link="chassis"/>
        <child link="leg_0_rotX"/>
        <axis xyz="1.0 0.0 0.0"/>
        <limit lower="-0.523599" upper="0.523599" effort="1000.0" velocity="0.5"/>
        <origin xyz="0.265  0 0.014" rpy="0.0 0.0 0"/>
    </joint>
    <joint name="leg_1_LCSX" type="revolute">
        <parent link="chassis"/>
        <child link="leg_1_rotX"/>
        <axis xyz="1.0 0.0 0.0"/>
        <limit lower="-0.523599" upper="0.523599" effort="1000.0" velocity="0.5"/>
        <origin xyz="-0.1325  -0.2294967320017 0.014" rpy="0.0 0.0 -2.0943951023931953"/>
    </joint>
    <joint name="leg_2_LCSX" type="revolute">
        <parent link="chassis"/>
        <child link="leg_2_rotX"/>
        <axis xyz="1.0 0.0 0.0"/>
        <limit lower="-0.523599" upper="0.523599" effort="1000.0" velocity="0.5"/>
        <origin xyz="-0.1325  0.2294967320017 0.014" rpy="0.0 0.0 -4.1887902047863905"/>
    </joint>

    <joint name="leg_0_LCSY" type="revolute">
        <parent link="leg_0_rotX"/>
        <child link="leg_0_rotY"/>
        <axis xyz="0.0 1.0 0.0"/>
        <limit lower="-0.523599" upper="0.523599" effort="1000.0" velocity="0.5"/>            
    </joint>
    <joint name="leg_1_LCSY" type="revolute">
        <parent link="leg_1_rotX"/>
        <child link="leg_1_rotY"/>
        <axis xyz="0.0 1.0 0.0"/>
        <limit lower="-0.523599" upper="0.523599" effort="1000.0" velocity="0.5"/>            
    </joint>
    <joint name="leg_2_LCSY" type="revolute">
        <parent link="leg_2_rotX"/>
        <child link="leg_2_rotY"/>
        <axis xyz="0.0 1.0 0.0"/>
        <limit lower="-0.523599" upper="0.523599" effort="1000.0" velocity="0.5"/>            
    </joint>

    <joint name="leg_0_LCSZ" type="revolute">
        <parent link="leg_0_rotY"/>
        <child link="leg_0_drive_module"/>
        <axis xyz="0.0 0.0 1.0"/>
        <limit lower="-0.523599" upper="0.523599" effort="1000.0" velocity="0.5"/>            
    </joint>
    <joint name="leg_1_LCSZ" type="revolute">
        <parent link="leg_1_rotY"/>
        <child link="leg_1_drive_module"/>
        <axis xyz="0.0 0.0 1.0"/>
        <limit lower="-0.523599" upper="0.523599" effort="1000.0" velocity="0.5"/>            
    </joint>
    <joint name="leg_2_LCSZ" type="revolute">
        <parent link="leg_2_rotY"/>
        <child link="leg_2_drive_module"/>
        <axis xyz="0.0 0.0 1.0"/>
        <limit lower="-0.523599" upper="0.523599" effort="1000.0" velocity="0.5"/>            
    </joint>

    <joint name="leg_0/extend/joint" type="revolute">
        <parent link="leg_0_drive_module"/>
        <child link="leg_0_open"/>
        <axis xyz="0.0 1.0 0.0"/>
        <limit lower="-0.48869219055" upper="0.0034906585" effort="1000.0" velocity="0.5"/>
        <origin xyz="1.640 0.0 -0.037" rpy="0.0 -0.05235987756 0.0"/>
    </joint>
    <joint name="leg_1/extend/joint" type="revolute">
        <parent link="leg_1_drive_module"/>
        <child link="leg_1_open"/>
        <axis xyz="0.0 1.0 0.0"/>
        <limit lower="-0.48869219055" upper="0.0034906585" effort="1000.0" velocity="0.5"/>
        <origin xyz="1.640 0.0 -0.037" rpy="0.0 -0.05235987756 0.0"/>
    </joint>
    <joint name="leg_2/extend/joint" type="revolute">
        <parent link="leg_2_drive_module"/>
        <child link="leg_2_open"/>
        <axis xyz="0.0 1.0 0.0"/>
        <limit lower="-0.48869219055" upper="0.0034906585" effort="1000.0" velocity="0.5"/>
        <origin xyz="1.640 0.0 -0.037" rpy="0.0 -0.05235987756 0.0"/>
    </joint>

</robot>
